<?xml version="1.0"?>
<robot name="robotic_arm1" xmlns:xacro="http://www.ros.org/wiki/xacro">

    <xacro:include filename="$(find robotic_arm_description1)/urdf/materials.xacro" />

    <!-- Include Gazebo Parameters -->
    <xacro:include filename="$(find robotic_arm_description1)/urdf/robotic_arm1_gazebo.xacro" />

     <!-- Include ros2_control Plugins -->
     <xacro:include filename="$(find robotic_arm_description1)/urdf/robotic_arm1_ros2_control.xacro" />
    

    <!-- Useful XACRO Variables (Properties) -->
    <xacro:property name="PI" value="3.14159265359" />
    <xacro:property name="effort" value="30.0" />
    <xacro:property name="velocity" value="10.0" />

    <!-- Useful Macros -->
    <xacro:macro name="default_inertial" params="mass">
        <inertial>
            <origin xyz="0 0 0" rpy="0 0 0" />
            <mass value="${mass}" />
            <inertia ixx="1.0" ixy="0.0" ixz="0.0"
                iyy="1.0" iyz="0.0"
                izz="1.0" />
        </inertial>
    </xacro:macro>

    <xacro:macro name="default_transmission" params="number">
        <transmission name="transmission_${number}">
            <plugin>transmission_interface/SimpleTransmission</plugin>
            <actuator name="motor_${number}" role="actuator1" />
            <joint name="joint_${number}" role="joint1">
                <mechanical_reduction>1.0</mechanical_reduction>
            </joint>
        </transmission>
    </xacro:macro>


    <!-- Links -->
    <link name="world" />

    <link name="base_link">
        <xacro:default_inertial mass="1.0" />
        <visual>
            <origin xyz="0 0 0" rpy="0 0 0" />
            <geometry>
                <mesh filename="package://robotic_arm_description1/meshes/base_link.stl"
                    scale="0.001 0.001 0.001" />
            </geometry>
            <material name="silver" />
        </visual>
        <collision>
            <origin xyz="0 0 0" rpy="0 0 0" />
            <geometry>
                <mesh filename="package://robotic_arm_description1/meshes/base_link.stl"
                    scale="0.001 0.001 0.001" />
            </geometry>
        </collision>
    </link>

    <link name="base_plate">
        <xacro:default_inertial mass=".5" />
        <visual>
            <origin xyz="-0.0 -0.0 -0.1" rpy="0 0 0" />
            <geometry>
                <mesh filename="package://robotic_arm_description1/meshes/link1_1.stl"
                    scale="0.001 0.001 0.001" />
            </geometry>
            <material name="silver" />
        </visual>
        <collision>
            <origin xyz="-0.0 -0.0 -0.1" rpy="0 0 0" />
            <geometry>
                <mesh filename="package://robotic_arm_description1/meshes/link1_1.stl"
                    scale="0.001 0.001 0.001" />
            </geometry>
        </collision>
    </link>

    <link name="link1">
        <xacro:default_inertial mass="0.5" />
        <visual>
            <origin xyz="-0.0 0.03 -0.18" rpy="0 0 0" />
            <geometry>
                <mesh filename="package://robotic_arm_description1/meshes/link2_1.stl"
                    scale="0.001 0.001 0.001" />
            </geometry>
            <material name="silver" />
        </visual>
        <collision>
            <origin xyz="-0.0 0.03 -0.18" rpy="0 0 0" />
            <geometry>
                <mesh filename="package://robotic_arm_description1/meshes/link2_1.stl"
                    scale="0.001 0.001 0.001" />
            </geometry>
        </collision>
    </link>

    <link name="link2">
        <xacro:default_inertial mass="0.5" />
        <visual>
            <origin xyz="-0.0 -0.02 -0.54" rpy="0 0 0" />
            <geometry>
                <mesh filename="package://robotic_arm_description1/meshes/link3_1.stl"
                    scale="0.001 0.001 0.001" />
            </geometry>
            <material name="silver" />
        </visual>
        <collision>
            <origin xyz="-0.0 -0.02 -0.54" rpy="0 0 0" />
            <geometry>
                <mesh filename="package://robotic_arm_description1/meshes/link3_1.stl"
                    scale="0.001 0.001 0.001" />
            </geometry>
        </collision>
    </link>

    <link name="link3">
        <xacro:default_inertial mass="0.4" />
        <visual>
            <origin xyz="-0.26 0.06 -0.54" rpy="0 0 0" />
            <geometry>
                <mesh filename="package://robotic_arm_description1/meshes/link4_1.stl"
                    scale="0.001 0.001 0.001" />
            </geometry>
            <material name="silver" />
        </visual>
        <collision>
            <origin xyz="-0.26 0.06 -0.54" rpy="0 0 0" />
            <geometry>
                <mesh filename="package://robotic_arm_description1/meshes/link4_1.stl"
                    scale="0.001 0.001 0.001" />
            </geometry>
        </collision>
    </link>

    <link name="link4">
        <xacro:default_inertial mass="0.3" />
        <visual>
            <origin xyz="-0.24 -0.0 -0.43" rpy="0 0 0" />
            <geometry>
                <mesh filename="package://robotic_arm_description1/meshes/link5_1.stl"
                    scale="0.001 0.001 0.001" />
            </geometry>
            <material name="silver" />
        </visual>
        <collision>
            <origin xyz="-0.24 -0.0 -0.43" rpy="0 0 0" />
            <geometry>
                <mesh filename="package://robotic_arm_description1/meshes/link5_1.stl"
                    scale="0.001 0.001 0.001" />
            </geometry>
        </collision>
    </link>


    <link name="gripper">
        <xacro:default_inertial mass="0.2" />

        <visual>
            <origin xyz="-0.295 -0.0 -0.37" rpy="0 0 0" />
            <geometry>
                <mesh filename="package://robotic_arm_description1/meshes/gripper_1.stl"
                    scale="0.001 0.001 0.001" />
            </geometry>
            <material name="silver" />
        </visual>
        <collision>
            <origin xyz="-0.295 -0.0 -0.37" rpy="0 0 0" />
            <geometry>
                <mesh filename="package://robotic_arm_description1/meshes/gripper_1.stl"
                    scale="0.001 0.001 0.001" />
            </geometry>
        </collision>
    </link>


    <!-- Joints -->
    <joint name="virtual_joint" type="fixed">
        <parent link="world" />
        <child link="base_link" />
        <origin xyz="0 0 0" rpy="0 0 0" />
    </joint>

    <joint name="joint_1" type="revolute">
        <origin xyz="0.0 0.0 0.1" rpy="0 0 0" />
        <parent link="base_link" />
        <child link="base_plate" />
        <axis xyz="0.0 0.0 1.0" />
        <limit upper="${PI/2}" lower="-${PI/2}" effort="${effort}" velocity="${velocity}"/>
    </joint>

    <joint name="joint_2" type="revolute">
        <origin xyz="0.0 -0.03 0.08" rpy="0 0 0" />
        <parent link="base_plate" />
        <child link="link1" />
        <axis xyz="0.0 1.0 0.0" />
        <limit upper="${PI/2}" lower="-${PI/4}" effort="${effort}" velocity="${velocity}"/>
    </joint>

    <joint name="joint_3" type="revolute">
        <origin xyz="0.0 0.05 0.36" rpy="0 0 0" />
        <parent link="link1" />
        <child link="link2" />
        <axis xyz="0.0 -1.0 0.0" />
        <limit upper="${PI/2}" lower="-${PI/3}" effort="${effort}" velocity="${velocity}"/>
    </joint>

    <joint name="joint_4" type="revolute">
        <origin xyz="0.26 -0.08 0.0" rpy="0 0 0" />
        <parent link="link2" />
        <child link="link3" />
        <axis xyz="0.0 1.0 0.0" />
        <limit upper="${PI/4}" lower="-2.356194" effort="${effort}" velocity="${velocity}"/>
    </joint>

    <joint name="joint_5" type="revolute">
        <origin xyz="-0.02 0.06 -0.11" rpy="0 0 0" />
        <parent link="link3" />
        <child link="link4" />
        <axis xyz="1.0 0.0 0.0" />
        <limit upper="${PI/2}" lower="-${PI/2}" effort="${effort}" velocity="${velocity}"/>
    </joint>

    

    <joint name="joint_6" type="revolute">
        <origin xyz="0.055 0.0 -0.06" rpy="0 0 0" />
        <parent link="link4" />
        <child link="gripper" />
        <axis xyz="0.0 0.0 -1.0" />
        <limit upper="4.712389" lower="0.0" effort="${effort}" velocity="${velocity}"/>
    </joint>


    <!-- Transmissions-->
    <xacro:default_transmission number="1" />
    <xacro:default_transmission number="2" />
    <xacro:default_transmission number="3" />
    <xacro:default_transmission number="4" />
    <xacro:default_transmission number="5" />
    <xacro:default_transmission number="6" />


</robot>